Workbook

Sheet Cover
C12: My Solar Light Company
C13: =TODAY() -> 46216
B24: 3 statement financial modelling

Sheet Dashboard
L1: Chart data (linked — do not edit)
B2: =Cover!C12 -> My Solar Light Company
L3: P&L Bridge
B4: ="Single-Site Solar Mini-Grid — FY"&Model!H2&" Performance Dashboard (₦)" -> Single-Site Solar Mini-Grid — FY2026 Performance Dashboard (₦) | L4: Revenue | M4: =Model!H107 -> 1902800880
L5: EBITDA | M5: =Model!H14 -> 1.7105729e+09
B6: FINANCIAL PERFORMANCE | L6: EBIT | M6: =Model!H16 -> 1.1834961e+09
B7: Revenue | D7: EBITDA | F7: Net Income | H7: DSCR | L7: Net Income | M7: =Model!H20 -> 3.696686e+08
B8: =Model!H10 -> 1902800880 | D8: =Model!H14 -> 1.7105729e+09 | F8: =Model!H20 -> 3.696686e+08 | H8: =Model!H263 -> 1.8406992
B9: Total FY revenue | D9: =TEXT(Model!H14/Model!H10,"0.0%")&" margin" -> 89.9% margin | F9: =TEXT(Model!H20/Model!H10,"0.0%")&" margin" -> 19.4% margin | H9: Debt service coverage | L9: Capital Structure
L10: Debt | M10: =Model!H190 -> 3.72e+09
B11: PROJECT & CAPITAL SNAPSHOT | L11: Equity | M11: =Model!H200 -> 2480000000
B12: Plant Capacity | C12: Annual Energy Gen. | D12: Customer Connections | E12: Total CAPEX | F12: Debt : Equity | G12: Loan Interest Rate | H12: Loan Tenor | I12: Avg. Tariff
B13: =Assumptions!E5&" MW" -> 5 MW | C13: =TEXT(Assumptions!E10,"#,##0")&" MWh" -> 9,636 MWh | D13: =TEXT(Assumptions!E26,"#,##0") -> 4,500 | E13: =TEXT(Assumptions!E31,"0.0")&"bn" -> 6.2bn | F13: =TEXT(Assumptions!E32,"0%")&" : "&TEXT(Assumptions!E33,"0%") -> 60% : 40% | G13: =TEXT(Assumptions!E34,"0%") -> 18% | H13: =Assumptions!E35&" yrs" -> 10 yrs | I13: =Assumptions!E25&" ₦/kWh" -> 180 ₦/kWh | L13: Credit Metrics
L14: Debt / EBITDA | M14: =(Model!H40+Model!H43)/Model!H14 -> 2.082253
B15: VISUAL SUMMARY | L15: Debt-to-Capital | M15: =(Model!H40+Model!H43)/(Model!H40+Model!H43+Model!H50) -> 0.5555389

Sheet Assumptions
A2: Assumptions and drivers
B4: Operational drivers | E4: Value | H4: Technical Assumptions from Engineering team | I4: Value
B5: Plant Capacity | E5: 5 | H5: Installed Capacity | I5: 5 MW
B6: Operational Days | E6: 365 | H6: Solar Panel Rating | I6: 550 W
B7: Average Capacity Factor | E7: 0.22 | H7: Solar Panel Efficiency | I7: 0.218
B8: Distribution losses | E8: 0.05 | H8: Number of Panels | I8: ~9,091
B9: Billing efficiency | E9: 0.98 | H9: Inverter Efficiency | I9: 0.985
B10: Annual Energy Generated | E10: 9636 | H10: Capacity Factor | I10: 0.22
B11: Insurance rate | E11: 0.006 | H11: Distribution Losses | I11: 0.05
B12: Operating and maintenance of solar plant | E12: 25 | H12: Annual Energy Generated | I12: 9,636,000 kWh
B13: Each Technician Salary (₦) | E13: 6
B14: Each Operator Salary (₦) | E14: 5
B15: Operating expenses | E15: 0.01
B16: Inventory Days | E16: 30
B17: Payable Days | E17: 45 | H17: Description
B18: Prepaid Insurance | E18: Annual Insurance Premium | H18: Electricity Sales | I18: Sale of energy to customers based on kWh consumed
B19: Accrued Expenses | E19: One month operating expenses | H19: Fixed Service Charges | I19: Monthly fixed fee charged to connected customers
H20: Connection Fees | I20: One-time fees from new customer connections
B21: Note: The annual energy generation is calculated as: | H21: Maintenance Services | I21: Optional maintenance contracts for commercial customers
B22: 5 MW × 8,760 hours/year × 22% capacity factor = 9,636 MWh (9,636,000 kWh). | H22: Solar Panel Efficiency | I22: % of sunlight converted into electricity by the panel itself
H23: Capacity Factor | I23: % of the maximum possible energy a plant actually produces over a year
B24: Revenue drivers | E24: Value | I24: This accounts for energy that does not get to the customers
B25: Average Tariff (₦) | E25: 180 | H25: Billing Efficiency | I25: Delivered energy is billed due to meter errors or other technical issues
B26: Customer Connections | E26: 4500
B27: Monthly Service Fee (₦) | E27: 2000
B28: New Connection Fee (₦) | E28: 40000
B30: Financing drivers | E30: Value
B31: Project Construction Cost (₦) | E31: 6.2
B32: Debt Financing | E32: 0.6
B33: Equity Financing | E33: 0.4
B34: Loan Interest Rate | E34: 0.18
B35: Loan Tenor | E35: 10
B36: Repayment | E36: Equal payments
B37: Interest earned on cash balance | E37: 0.02
B38: Corporate Tax Rate (cash paid) | E38: 0.3
B40: Solar Plant Asset | C40: % of Total CAPEX | D40: Useful Years | E40: EPC allocation
B41: Solar PV Panels | C41: 0.3 | D41: 20 | E41: 0.2
B42: Battery ESS | C42: 0.23 | D42: 7 | E42: 0.25
B43: Inverters | C43: 0.08 | D43: 10 | E43: 0.18
B44: Mounting Structures | C44: 0.05 | D44: 20 | E44: 0.12
...

Sheet Model
A1: FINANCIAL STATEMENTS
H2: =YEAR(TODAY()) -> 2026
H3: ₦
B4: Income statement
C6: Revenue
D7: Electricity sales | H7: =Model!H92 -> 1614800880
D8: Connection fess | H8: =Model!H98 -> 180000000
D9: Fixed service charges | H9: =Model!H105 -> 108000000
H10: =SUM(H7:H9) -> 1902800880
C11: Cost of sales | H11: =-Model!H123 -> -173200000
C12: Gross Profit | H12: =SUM(H10:H11) -> 1729600880
C13: Operating expenses | H13: =-H127 -> -19028009
C14: EBITDA | H14: =SUM(H12:H13) -> 1.7105729e+09
C15: D&A | H15: =-SUM(Model!C170:K170) -> -5.2707676e+08
C16: EBIT | H16: =SUM(H14:H15) -> 1.1834961e+09
C17: Interest expenses | H17: =-H188 -> -6.5539811e+08
C18: EBT | H18: =SUM(H16:H17) -> 5.28098e+08
C19: Taxes | H19: =-Assumptions!E38*H18 -> -1.584294e+08
C20: Net Income | H20: =SUM(H18:H19) -> 3.696686e+08
B22: Balance Sheet
C24: ASSETS
D25: Cash | H25: =H78 -> 7.1009437e+08
D26: Accounts Receivable | H26: =H147 -> 0
D27: Inventory | H27: =H148 -> 14235616
D28: Prepaid Expenses | H28: =H149 -> 37200000
D29: Total Current Assets | H29: =SUM(H25:H28) -> 7.6152999e+08
D31: Net PP&E | H31: =L171 -> 5.6729232e+09
D32: Other | H32: 0
D33: Total Long Term Assets | H33: =SUM(H31:H32) -> 5.6729232e+09
D35: Total Assets | H35: =H29+H33 -> 6.4344532e+09
C37: LIABILITIES AND EQUITY
D38: Accounts Payable | H38: =H150 -> 21353425
D39: Accrued expenses | H39: =H151 -> 1585667.4
D40: Current Loan | H40: =H194 -> 1.8662227e+08
D41: Total Current Liabilities | H41: =SUM(H38:H40) -> 2.0956136e+08
D43: Non current loan | H43: =H195 -> 3.3752233e+09
D44: Total Long Term Liabilities | H44: =SUM(H43) -> 3.3752233e+09
D46: Total Liabilities | H46: =H41+H44 -> 3.5847846e+09
D48: Common Shares | H48: =H200 -> 2480000000
D49: Retained Earnings | H49: =H20 -> 3.696686e+08
...
